Workbook
Name __Att1: #REF!
Name __Att10: #REF!
Name __Att2: #REF!
Name __Att3: #REF!
Name __Att4: #REF!
Name __Att5: #REF!
Name __Att6: #REF!
Name __Att7: #REF!
Name __Att8: #REF!
Name __Att9: #REF!
Name __MAT2: #REF!
Name __prn50: #REF!
Name _Att1: #REF!
Name _Att10: #REF!
Name _Att2: #REF!
Name _Att3: #REF!
Name _Att4: #REF!
Name _Att5: #REF!
Name _Att6: #REF!
Name _Att7: #REF!
Name _Att8: #REF!
Name _Att9: #REF!
Name _MA1: #REF!
Name _MA2: #REF!
Name _MAT2: #REF!
Name _PO1: #REF!
Name _PO2: #REF!
Name _prn50: #REF!
Name _Z1Code: #REF!
Name _Z1Name: #REF!
Name _Z2Code: #REF!
Name _Z2Name: #REF!
Name _Z2Z1Link: #REF!
Name _Z3Period: #REF!
Name _Z3Shift: #REF!
Name _Z4Losses: #REF!
Name _Z4Name: #REF!
Name _Z4Time: #REF!
Name a: #REF!
Name Accidents: #REF!
Name ACTIONS: '[1]Piano d''Azione 1'!$I$4
Name attendace: #REF!
Name auditor: #REF!
Name CoefEnergy: #REF!
Name CoefLabor: #REF!
Name CoefQty: #REF!
Name CoefScrap: #REF!
Name Coefscrap2: #REF!
Name CostLabor: #REF!
Name data: #REF!
Name date: '[2]Prob. Res. Index'!#REF!
Name defpareto: #REF!
Name department: #REF!
Name deviation: #REF!
Name deviation2: #REF!
Name edgj: #REF!
Name eee: [3]Tags!$C$7:$C$9
Name eeee: '[4]Registro TAGS'!$F$1
Name FIBER1: #REF!
Name helpRow: [5]Master_Plan_GanttChart!#REF!

Sheet 01. OE Team
A1: OPERATIONS EXCELLENCE TEAM
A2: Leader | B2: Picture | C2: Main Function | D2: OE Function | E2: Implementation tools | H2: Responsible | I2: Related area | J2: Contact
A3: Duy Phạm | C3: Production Lead | D3: OE Coordinator | E3: OE Connection | H3: Connect all Pillars to a dashboard of execution. Following activities of all pillars to call support ontime. | I3: OE team | J3: Email: duy.pham@ild-coffee.com Phone: +84384613654
A4: Duy Phạm | C4: Production Lead | D4: AM Pillar Lead | E4: Cleaning standard | F4: Inspection standard | G4: Centerline standard | H4: Eliminate or reduce the forced failure to minimize the Operation performance loss. | I4: Tipping Coffee processing Utility | J4: Email: duy.pham@ild-coffee.com Phone: +84384613654
A5: Dung Trần | C5: Quality Manager | D5: GA Pillar Lead | E5: MOR/WOR/DOR/SHO | F5: Measure cascading (KPI/PPI/API) | H5: Ensure all OE' team activities are connected to business strategy and objectives, creating alignment and commitment across all levels | I5: Whole factory | J5: Email: dung.tran@ild-coffee.com Phone: +84975507180
A6: Vũ Trần | C6: R&D Lead | D6: FI Pillar Lead | E6: RCA DMAIC | F6: IPA | G6: KLL | H6: Using the tools for data analysis & troubleshooting to improve equipment efficiency & optimize the costs. | I6: Whole factory | J6: Email: vu.tran@ild-coffee.com Phone: +84973846326
A7: Bình Đặng | C7: Food Safety Supervisor | D7: Quality Pillar Lead | E7: Q line mapping Microbiology | F7: Q line mapping Foreinbody | H7: Prevent defects at the source, maintain stable equipment and processes to achieve “Zero Defect,” and enhance customer satisfaction. | I7: Coffee processing | J7: Email: binh.dang@ild-coffee.com Phone: +84976667041
A8: Thu Dương | C8: HR Specilist | D8: E&T Pillar Lead | E8: Competency matrix | F8: Multi-skilled Program | H8: Manage & develop competency across the organization to ensure effective and sustainable OE implementation. | I8: Whole factory | J8: Email: thu.duong@ild-coffee.com Phone:+84985213615
A9: Anh Trương | C9: Maintenance Planning Supervisor | D9: PM Pillar Lead | E9: PM Master Plan | F9: SOP/Tasklist management | G9: Spare part management | H9: Prevent breakdowns, optimize costs, and ensure long-term stable equipment performance through planned and predictive maintenance | I9: Whole factory | J9: Email: anh.truong@ild-coffee.com Phone: +84908566393
A10: Hoàng Nguyễn | C10: SHE Manager | D10: SHE Pillar Lead | E10: 5S Phase 2 | F10: LOTO | G10: CSD | H10: Ensure safety, health, and environmental protection through standardized equipment, processes, and behaviors. Enhance 5S standard for the whole factory | I10: Whole factory | J10: Email: hoang.nguyen@ild-coffee.com Phone: +84329501881
A11: Đức Mai | C11: OPs Manager | D11: OE Leader | E11: All | J11: Email: duc.mai@ild-coffee.com Phone: + 84975232032

Sheet 01. Steering Committee
B1: STRATEGY | D1: GOAL ALIGNMENT | F1: TPM
A2: Role | B2: Sponsor | C2: OE Leader | D2: OE Coordinator | E2: GA Pillar Leader | F2: TPM - SHE Pillar Leader | G2: TPM - Q Pillar Leader | H2: TPM - AM Pillar Leader | I2: TPM - PM Pillar Leader | J2: TPM - FI Pillar Leader | K2: TPM - E&T Pillar Leader
A3: Name | B3: Thi Nguyen | C3: Duc Mai | D3: Duy Pham | E3: Dung Tran | F3: Hoang Nguyen | G3: Dung Tran | H3: Duy Pham | I3: Anh Truong | J3: Vu Tran | K3: Thu Duong
A4: Responsibility | B4: Advise, Challenge, Strategy Decision maker, Motivation, Budget | C4: Ensure methodology, alignment, timeline, effectiveness of all pillars. Key person to align strategy with GD | D4: Connect all Pillars to a dashboard of execution. Following activities of all pillars to call support ontime. | E4: On top of methodology. A person to decide the approach of methodology of this pillar to build the basic foudation of ILD | F4: On top of methodology. Ensure safety, health, and environmental protection through standardized equipment, processes, and behaviors. Enhance 5S standard for the whole factory | G4: On top of methodology. A person to decide the approach of methodology of this pillar to build quality methodology to ensure the good product for customer | H4: On top of methodology. A person to decide the approach of methodology of this pillar to build the back bone of TPM to prevent the force deterioration of machine | I4: On top of methodology. A person to decide the approach of methodology of this pillar to Preventive Maintenance to prevent the natural deterioration of machine | J4: On top of methodology. A person to decide the approach of methodology of this pillar to build problem solving methodology for all pillars | K4: On top of methodology. A person to decide the approach of methodology of this pillar to build training plan & ensure people competency

Sheet 02. RASCI

Sheet 03. Attendance
A1: OPERATIONS EXCELLANCE WEEKLY MEETING - ATTENDANCE TRACKING
A2: No | B2: Leader | C2: Pillar | D2: NOTE | E2: Mar | G2: Apr | I2: May | K2: Jun | M2: Jul | O2: Aug | R2: Sep | T2: Oct | V2: Nov | X2: Dec | Z2: Punish | AK2: =12-3 -> 9
E3: Week 2 | F3: Week 4 | G3: Week 2 | H3: Week 4 | I3: Week 2 | J3: Week 4 | K3: Week 2 | L3: Week 4 | M3: Week 2 | N3: Week 4 | O3: Week 1 | P3: Week 2 | Q3: Week 4 | R3: Week 2 | S3: Week 4 | T3: Week 2 | U3: Week 4 | V3: Week 2 | W3: Week 4 | X3: Week 2 | Y3: Week 4 | Z3: Attendance | AA3: Action Plan | AB3: Milestone | AC3: Total | AD3: Fine paid | AE3: Remain | AH3: OE Team | AI3: date | AJ3: set | AK3: count M | AL3: pay-ins | AM3: Q2 | AN3: Q3 | AO3: Q4
A4: 1 | B4: Duc Mai | C4: OE | D4: Mandatory | E4: 1 | F4: 1 | G4: 1 | H4: 1 | I4: 1 | J4: 1 | K4: 1 | L4: 1 | M4: 3 | N4: 3 | O4: 1 | P4: 1 | Q4: 1 | Z4: =(COUNTIF(I4:Y4,"2")*20000)+(COUNTIF(I4:Y4,"3")*50000) -> 100000 | AA4: =(SUMIF('06. Action Plan'!$E$2:$E$149,TRIM('03. Attendance'!B4),'06. Action Plan'!$I$2:$I$149))*10000 -> 0 | AB4: =SUMIF('05. Master Planning'!$C$5:$C$55,TRIM('03. Attendance'!B4),'05. Master Planning'!$BF$5:$BF$55) -> 0 | AC4: =SUM(Z4:AB4) -> 100000 | AD4: 100000 | AE4: =AC4-AD4 -> 0 | AH4: Duc Mai | AI4: 46148 | AJ4: 200000 | AK4: =AL4/AJ4 -> 6 | AL4: =SUM(AM4:AO4) -> 1200000 | AM4: 600000 | AN4: 600000 | AO4: 0
A5: 2 | B5: Duy Pham | C5: AM/Coor. | D5: Mandatory | E5: 1 | F5: 1 | G5: 1 | H5: 1 | I5: 1 | J5: 1 | K5: 1 | L5: 1 | M5: 1 | N5: 1 | O5: 1 | P5: 1 | Q5: 1 | Z5: =(COUNTIF(I5:Y5,"2")*20000)+(COUNTIF(I5:Y5,"3")*50000) -> 0 | AA5: =(SUMIF('06. Action Plan'!$E$2:$E$149,TRIM('03. Attendance'!B5),'06. Action Plan'!$I$2:$I$149))*10000 -> 10000 | AB5: =SUMIF('05. Master Planning'!$C$5:$C$55,TRIM('03. Attendance'!B5),'05. Master Planning'!$BF$5:$BF$55) -> 0 | AC5: =SUM(Z5:AB5) -> 10000 | AD5: 10000 | AE5: =AC5-AD5 -> 0 | AH5: Duy Pham | AI5: 46147 | AJ5: 100000 | AK5: =AL5/AJ5 -> 6 | AL5: =SUM(AM5:AO5) -> 600000 | AM5: 300000 | AN5: 300000 | AO5: 0
A6: 3 | B6: Dung Tran | C6: GA | D6: Mandatory | E6: 1 | F6: 2 | G6: 2 | H6: 3 | I6: 1 | J6: 1 | K6: 1 | L6: 1 | M6: 3 | N6: 2 | O6: 2 | P6: 1 | Q6: 3 | Z6: =(COUNTIF(I6:Y6,"2")*20000)+(COUNTIF(I6:Y6,"3")*50000) -> 140000 | AA6: =(SUMIF('06. Action Plan'!$E$2:$E$149,TRIM('03. Attendance'!B6),'06. Action Plan'!$I$2:$I$149))*10000 -> 10000 | AB6: =SUMIF('05. Master Planning'!$C$5:$C$55,TRIM('03. Attendance'!B6),'05. Master Planning'!$BF$5:$BF$55) -> 0 | AC6: =SUM(Z6:AB6) -> 150000 | AD6: 80000 | AE6: =AC6-AD6 -> 70000 | AH6: Dung Tran | AI6: 46150 | AJ6: 200000 | AK6: =AL6/AJ6 -> 6 | AL6: =SUM(AM6:AO6) -> 1200000 | AM6: 600000 | AN6: 600000 | AO6: 0
A7: 4 | B7: Vu Tran | C7: FI | D7: Mandatory | E7: 1 | F7: 2 | G7: 1 | H7: 1 | I7: 1 | J7: 1 | K7: 1 | L7: 1 | M7: 1 | N7: 1 | O7: 1 | P7: 1 | Q7: 1 | Z7: =(COUNTIF(I7:Y7,"2")*20000)+(COUNTIF(I7:Y7,"3")*50000) -> 0 | AA7: =(SUMIF('06. Action Plan'!$E$2:$E$149,TRIM('03. Attendance'!B7),'06. Action Plan'!$I$2:$I$149))*10000 -> 10000 | AB7: =SUMIF('05. Master Planning'!$C$5:$C$55,TRIM('03. Attendance'!B7),'05. Master Planning'!$BF$5:$BF$55) -> 30000 | AC7: =SUM(Z7:AB7) -> 40000 | AD7: 40000 | AE7: =AC7-AD7 -> 0 | AH7: Vu Tran | AI7: 46150 | AJ7: 100000 | AK7: =AL7/AJ7 -> 6 | AL7: =SUM(AM7:AO7) -> 600000 | AM7: 300000 | AN7: 300000 | AO7: 0
A8: 5 | B8: Nghia Bui | C8: PM | D8: Mandatory | E8: 1 | F8: 3 | G8: 1 | H8: 1 | I8: 2 | J8: 2 | K8: 1 | L8: 3 | M8: 1 | N8: 1 | O8: 2 | P8: 1 | Q8: 1 | Z8: =(COUNTIF(O8:Y8,"2")*20000)+(COUNTIF(O8:Y8,"3")*50000) -> 20000 | AA8: =(SUMIF('06. Action Plan'!$E$2:$E$149,TRIM('03. Attendance'!B8),'06. Action Plan'!$I$2:$I$149))*10000 -> 0 | AB8: =SUMIF('05. Master Planning'!$C$5:$C$55,TRIM('03. Attendance'!B8),'05. Master Planning'!$BF$5:$BF$55) -> 10000 | AC8: =SUM(Z8:AB8) -> 30000 | AD8: 20000 | AE8: =AC8-AD8 -> 10000 | AH8: Nghia Bui | AI8: 46178 | AJ8: 100000 | AK8: =AL8/AJ8 -> 6 | AL8: =SUM(AM8:AO8) -> 600000 | AM8: 300000 | AN8: 300000 | AO8: 0
A9: 6 | B9: Binh Dang | C9: Q | D9: Mandatory | E9: 1 | F9: 3 | G9: 2 | H9: 3 | I9: 1 | J9: 1 | K9: 1 | L9: 2 | M9: 1 | N9: 1 | O9: 1 | P9: 1 | Q9: 3 | Z9: =(COUNTIF(I9:Y9,"2")*20000)+(COUNTIF(I9:Y9,"3")*50000) -> 70000 | AA9: =(SUMIF('06. Action Plan'!$E$2:$E$149,TRIM('03. Attendance'!B9),'06. Action Plan'!$I$2:$I$149))*10000 -> 0 | AB9: =SUMIF('05. Master Planning'!$C$5:$C$55,TRIM('03. Attendance'!B9),'05. Master Planning'!$BF$5:$BF$55) -> 0 | AC9: =SUM(Z9:AB9) -> 70000 | AD9: 20000 | AE9: =AC9-AD9 -> 50000 | AH9: Binh Dang | AI9: 46150 | AJ9: 100000 | AK9: =AL9/AJ9 -> 6 | AL9: =SUM(AM9:AO9) -> 600000 | AM9: 300000 | AN9: 300000 | AO9: 0
A10: 7 | B10: Thu Duong | C10: E&T | D10: Mandatory | E10: 1 | F10: 1 | G10: 1 | H10: 1 | I10: 1 | J10: 1 | K10: 1 | L10: 1 | M10: 1 | N10: 1 | O10: 2 | P10: 3 | Q10: 1 | Z10: =(COUNTIF(I10:Y10,"2")*20000)+(COUNTIF(I10:Y10,"3")*50000) -> 70000 | AA10: =(SUMIF('06. Action Plan'!$E$2:$E$149,TRIM('03. Attendance'!B10),'06. Action Plan'!$I$2:$I$149))*10000 -> 0 | AB10: =SUMIF('05. Master Planning'!$C$5:$C$55,TRIM('03. Attendance'!B10),'05. Master Planning'!$BF$5:$BF$55) -> 20000 | AC10: =SUM(Z10:AB10) -> 90000 | AD10: 10000 | AE10: =AC10-AD10 -> 80000 | AH10: Thu Duong | AI10: 46148 | AJ10: 100000 | AK10: =AL10/AJ10 -> 6 | AL10: =SUM(AM10:AO10) -> 600000 | AM10: 300000 | AN10: 300000 | AO10: 0
A11: 8 | B11: Hoang Nguyen | C11: SHE | D11: Mandatory | E11: 1 | F11: 1 | G11: 1 | H11: 1 | I11: 1 | J11: 1 | K11: 1 | L11: 1 | M11: 1 | N11: 1 | O11: 1 | P11: 1 | Q11: 3 | Z11: =(COUNTIF(I11:Y11,"2")*20000)+(COUNTIF(I11:Y11,"3")*50000) -> 50000 | AA11: =(SUMIF('06. Action Plan'!$E$2:$E$149,TRIM('03. Attendance'!B11),'06. Action Plan'!$I$2:$I$149))*10000 -> 0 | AB11: =SUMIF('05. Master Planning'!$C$5:$C$55,TRIM('03. Attendance'!B11),'05. Master Planning'!$BF$5:$BF$55) -> 20000 | AC11: =SUM(Z11:AB11) -> 70000 | AD11: 20000 | AE11: =AC11-AD11 -> 50000 | AH11: Hoang Nguyen | AI11: 46148 | AJ11: 200000 | AK11: =AL11/AJ11 -> 6 | AL11: =SUM(AM11:AO11) -> 1200000 | AM11: 600000 | AN11: 600000 | AO11: 0
A12: 9 | B12: Yen Tran | C12: Support E&T | D12: Mandatory | E12: 4 | F12: 1 | G12: 4 | H12: 1 | I12: 2 | J12: 3 | K12: 1 | L12: 3 | M12: 2 | Z12: =(COUNTIF(I12:Y12,"2")*20000)+(COUNTIF(I12:Y12,"3")*50000) -> 140000 | AA12: =(SUMIF('06. Action Plan'!$E$2:$E$149,TRIM('03. Attendance'!B12),'06. Action Plan'!$I$2:$I$149))*10000 -> 10000 | AB12: =SUMIF('05. Master Planning'!$C$5:$C$55,TRIM('03. Attendance'!B12),'05. Master Planning'!$BF$5:$BF$55) -> 0 | AC12: =SUM(Z12:AB12) -> 150000 | AE12: =AC12-AD12 -> 150000 | AH12: Yen Tran | AJ12: 200000 | AK12: =AL12/AJ12 -> 0 | AL12: =SUM(AM12:AO12) -> 0 | AM12: 0 | AN12: 0 | AO12: 0
A13: 10 | B13: Thang Cao | C13: Support PM | D13: Mandatory | E13: 4 | F13: 4 | G13: 4 | H13: 4 | I13: 2 | J13: 1 | K13: 2 | L13: 1 | M13: 2 | Z13: =(COUNTIF(I13:Y13,"2")*20000)+(COUNTIF(I13:Y13,"3")*50000) -> 60000 | AA13: =(SUMIF('06. Action Plan'!$E$2:$E$149,TRIM('03. Attendance'!B13),'06. Action Plan'!$I$2:$I$149))*10000 -> 0 | AB13: =SUMIF('05. Master Planning'!$C$5:$C$55,TRIM('03. Attendance'!B13),'05. Master Planning'!$BF$5:$BF$55) -> 0 | AC13: =SUM(Z13:AB13) -> 60000 | AD13: 40000 | AE13: =AC13-AD13 -> 20000 | AH13: Thang Cao | AI13: 46148 | AJ13: 200000 | AK13: =AL13/AJ13 -> 3 | AL13: =SUM(AM13:AO13) -> 600000 | AM13: 600000 | AN13: 0 | AO13: 0
AC14: =SUM(AC4:AC11) -> 560000 | AD14: =SUM(AD4:AD13) -> 340000 | AE14: =SUM(AE4:AE11) -> 260000 | AL14: =SUM(AL4:AL13) -> 7200000
C15: 1 | D15: Ontime
C16: 2 | D16: Late
C17: 3 | D17: Absent
C18: 4 | D18: NA

Sheet 04. Agenda
B1: OE WEEKLY MEETING AGENDA
B2: Time: 11:00 - 12:00 Every 2 weeks Duration: 60 minutes
C3: Content | E3: Duration (min) | F3: PIC
B4: Plan | C4: Review Action Plan | E4: 10 | F4: Duy Pham
B5: KPI | C5: Monthly review Factory KPI | E5: 10 | F5: Duy Pham | G5: Review at the 1st meeting of the month
B6: Plan | C6: Review Master Plan & Milestones | E6: 15 | F6: Duy Pham
B7: Project | C7: Define next actions | E7: 20 | F7: All
B8: Support | C8: Escalation & Information | E8: 15 | F8: All

Sheet 05. Master Planning
A1: OPERATIONAL EXCELLENCE MASTER PLAN-2026 | BF1: Week | BG1: =WEEKNUM(TODAY(),2) -> 36
BF2: 1 | BG2: Milestone
A3: PILLAR | B3: KEY ACTIVITIES | C3: PIC | D3: MEMBER | E3: Jan | I3: Feb | M3: Mar | Q3: Apr | U3: May | AA3: Jun | AE3: Jul | AJ3: Aug | AN3: Sep | AS3: Oct | AW3: Nov | BA3: Dec | BF3: 2 | BG3: Done
E4: 1 | F4: 2 | G4: 3 | H4: 4 | I4: 5 | J4: 6 | K4: 7 | L4: 8 | M4: 9 | N4: 10 | O4: 11 | P4: 12 | Q4: 13 | R4: 14 | S4: 15 | T4: 16 | U4: 17 | V4: 18 | W4: 19 | X4: 20 | Y4: 21 | Z4: 22 | AA4: 23 | AB4: 24 | AC4: 25 | AD4: 26 | AE4: 27 | AF4: 28 | AG4: 29 | AH4: 30 | AI4: 31 | AJ4: 32 | AK4: 33 | AL4: 34 | AM4: 35 | AN4: 36 | AO4: 37 | AP4: 38 | AQ4: 39 | AR4: 40 | AS4: 41 | AT4: 42 | AU4: 43 | AV4: 44 | AW4: 45 | AX4: 46 | AY4: 47 | AZ4: 48 | BA4: 49 | BB4: 50 | BC4: 51 | BD4: 52 | BF4: 3 | BG4: Late
A5: GA-GOAL ALIGNMENT | B5: Finalize GA Assessment Checklist | C5: Dung Tran | D5: Duc Mai | O5: 2 | BF5: =COUNTIF(U5:BD5,"3")*10000 -> 0
B6: Finalize Department KPI/PPI/API | C6: Dung Tran | D6: Duc Mai | P6: 2 | BF6: =COUNTIF(U6:BD6,"3")*10000 -> 0
B7: Regularly attend the Production/ENG/QA-Shift handover meeting (Sharing/Coaching/Recognizing) | C7: Dung Tran | D7: Duy Pham | S7: 3 | V7: 2 | AG7: 1 | AI7: 2 | AT7: 1 | BF7: =COUNTIF(U7:BD7,"3")*10000 -> 0
B8: Regularly attend the QA-WOR (Sharing/Coaching/Recognizing) | C8: Vu Tran | D8: Duy Pham | T8: 3 | V8: 2 | AH8: 3 | AJ8: 2 | AU8: 1 | BF8: =COUNTIF(U8:BD8,"3")*10000 -> 10000
B9: Regularly attend the Engineering-WOR (Sharing/Coaching/Recognizing) | C9: Dung Tran | D9: Duc Mai | V9: 2 | AJ9: 2 | AW9: 1 | BF9: =COUNTIF(U9:BD9,"3")*10000 -> 0
B10: Regularly attend the OPs-WOR (Sharing/Coaching/Recognizing) | C10: Dung Tran | D10: Nghia Bui | AA10: 2 | AN10: 1 | BA10: 1 | BF10: =COUNTIF(U10:BD10,"3")*10000 -> 0
B11: Monthly meeting to Review Project 2026 | C11: Duy Pham | D11: All | O11: 2 | S11: 2 | X11: 2 | AC11: 2 | AG11: 2 | AK11: 2 | AP11: 1 | AT11: 1 | AX11: 1 | BC11: 1 | BF11: =COUNTIF(U11:BD11,"3")*10000 -> 0
A12: AM-AUTONOMOUS MAINTENANCE | B12: Finalize OE Final Assessment Checklist | C12: Duy Pham | D12: Duc Mai | O12: 2 | BF12: =COUNTIF(U12:BD12,"3")*10000 -> 0
B13: FP&FD Working Group-OE Final Assessment | C13: Duy Pham | D13: OE team | AD13: 2 | BF13: =COUNTIF(U13:BD13,"3")*10000 -> 0
B14: ROA Working Group-OE Final Assessment | C14: Duy Pham | D14: OE team | AG14: 2 | BF14: =COUNTIF(U14:BD14,"3")*10000 -> 0
B15: EXT&EVAP Working Group-OE Final Assessment | C15: Duy Pham | D15: OE team | AM15: 2 | BF15: =COUNTIF(U15:BD15,"3")*10000 -> 0
B16: GRASSO Working Group-OE Final Assessment | C16: Duy Pham | D16: OE team | AO16: 1 | BF16: =COUNTIF(U16:BD16,"3")*10000 -> 0
B17: BOILER Working Group-OE Final Assessment | C17: Duy Pham | D17: OE team | AS17: 1 | BF17: =COUNTIF(U17:BD17,"3")*10000 -> 0
B18: WTP/WWTP Working Group-OE Final Assessment | C18: Duy Pham | D18: OE team | AW18: 1 | BF18: =COUNTIF(U18:BD18,"3")*10000 -> 0
B19: TIP Working Group-OE Final Assessment | C19: Duy Pham | D19: OE team | BA19: 1 | BF19: =COUNTIF(U19:BD19,"3")*10000 -> 0
A20: FI-FOCUS IMPROVEMENT | B20: Monthly Review RCA Effectiveness | C20: Vu Tran | D20: Duc Mai Dung Tran Duy Pham Nghia Bui | J20: 2 | N20: 2 | R20: 2 | V20: 3 | Y20: 2 | AB20: 2 | AE20: 2 | AJ20: 2 | AO20: 1 | AS20: 1 | AX20: 1 | BB20: 1 | BF20: =COUNTIF(U20:BD20,"3")*10000 -> 10000
B21: Monthly Tracking IPA (send monthly report) | C21: Vu Tran | D21: Vu Tran | I21: 2 | M21: 2 | Q21: 3 | R21: 3 | S21: 2 | V21: 2 | AB21: 2 | AF21: 3 | AK21: 2 | AO21: 1 | AS21: 1 | AX21: 1 | BB21: 1 | BF21: =COUNTIF(U21:BD21,"3")*10000 -> 10000
B22: Implement DMAIC for FD | C22: Vu Tran | D22: Vu Tran | Z22: 2 | BF22: =COUNTIF(U22:BD22,"3")*10000 -> 0
A23: E&T-EDUCATION & TRAINING | B23: Finalize CM for Production | C23: Thu Duong | D23: Yen Tran | P23: 3 | Q23: 2 | BF23: =COUNTIF(U23:BD23,"3")*10000 -> 0
B24: Finalize CM for Engineering | C24: Thu Duong | D24: Yen Tran | R24: 2 | BF24: =COUNTIF(U24:BD24,"3")*10000 -> 0
B25: Finalize CM for QA | C25: Thu Duong | D25: Yen Tran | R25: 2 | BF25: =COUNTIF(U25:BD25,"3")*10000 -> 0
B26: Finalize CM for WH | C26: Thu Duong | D26: Yen Tran | R26: 2 | BF26: =COUNTIF(U26:BD26,"3")*10000 -> 0
B27: Buildup Multi-skilled plan | C27: Thu Duong | D27: Yen Tran | P27: 3 | Q27: 2 | BF27: =COUNTIF(U27:BD27,"3")*10000 -> 0
B28: Monthly tracking Multi-skilled achievement | C28: Thu Duong | D28: Yen Tran | T28: 2 | Y28: 2 | AC28: 3 | AD28: 2 | AH28: 3 | AL28: 2 | AP28: 1 | AU28: 1 | AY28: 1 | BC28: 1 | BF28: =COUNTIF(U28:BD28,"3")*10000 -> 20000
A29: QA-QUALITY ASSURANCE | B29: Finalize Q-Line mapping for Microbiology | C29: Binh Dang | D29: Dung Tran | Z29: 2 | BF29: =COUNTIF(U29:BD29,"3")*10000 -> 0
B30: Monitor Q-Line mapping for Micro effectiveness | C30: Binh Dang | D30: Dung Tran | AC30: 2 | AH30: 2 | AL30: 2 | AQ30: 1 | AU30: 1 | AY30: 1 | BD30: 1 | BF30: =COUNTIF(U30:BD30,"3")*10000 -> 0
B31: Finalize Q-Line mapping for Foreinbody | C31: Binh Dang | D31: Dung Tran | Z31: 2 | BF31: =COUNTIF(U31:BD31,"3")*10000 -> 0
B32: Monitor Q-Line mapping for FB effectiveness | C32: Binh Dang | D32: Dung Tran | AC32: 2 | AH32: 2 | AL32: 2 | AQ32: 1 | AU32: 1 | AY32: 1 | BD32: 1 | BF32: =COUNTIF(U32:BD32,"3")*10000 -> 0
A33: PLANNED MAINTENANCE | B33: Complete PM Master Plan for Coffee Processing (Tipping to FP) | C33: Nghia Bui | D33: Thang Cao | Z33: 2 | BF33: =COUNTIF(U33:BD33,"3")*10000 -> 0
B34: Complete PM Master Plan for Utility and Facility | C34: Nghia Bui | D34: Thang Cao | Z34: 2 | BF34: =COUNTIF(U34:BD34,"3")*10000 -> 0
B35: Complete the Spare part list of Coffee Processing (Tipping to FP) | C35: Nghia Bui | D35: Thang Cao | Y35: 2 | BF35: =COUNTIF(U35:BD35,"3")*10000 -> 0
B36: Complete the Spare part list of Utility and Facility | C36: Nghia Bui | D36: Thang Cao | Y36: 2 | BF36: =COUNTIF(U36:BD36,"3")*10000 -> 0
B37: Complete Spare part Management System | C37: Nghia Bui | D37: Thang Cao | AV37: 1 | BF37: =COUNTIF(U37:BD37,"3")*10000 -> 0
B38: List down M&I maintenance SOP and highlight the Critical SOP | C38: Nghia Bui | D38: Thang Cao | AL38: 2 | BF38: =COUNTIF(U38:BD38,"3")*10000 -> 0
B39: Complete the Critical SOP of M&I | C39: Nghia Bui | D39: Thang Cao | BA39: 1 | BF39: =COUNTIF(U39:BD39,"3")*10000 -> 0
B40: List down E&A maintenance SOP and highlight the Critical SOP | C40: Nghia Bui | D40: Thang Cao | AL40: 3 | BF40: =COUNTIF(U40:BD40,"3")*10000 -> 10000
...

Sheet 06. Action Plan
B1: ACTION PLAN
B2: No | C2: Pillar | D2: Action | E2: PIC | F2: Due Date | G2: Status | H2: Note | I2: Punish
B3: 1 | C3: PM | D3: Cập nhật thêm Key activities cho PM (Utility / Facility) | E3: Duy Pham | F3: 46108 | G3: Done | H3: Done
B4: 2 | C4: OE | D4: Finalize master timeline | E4: Duy Pham | F4: 46108 | G4: Done | H4: Done
B5: 3 | C5: PM | D5: Finalize key activities of PM | E5: Anh Truong | F5: 46101 | G5: Done | H5: Book a Duc,c Dung,Duy,a Hoang,a Thang
B6: 4 | C6: GA | D6: Create Shift brief/SHO instruction & share to team | E6: Dung Tran | F6: 46101 | G6: Done | H6: Duc, Dung,Duy go together
B7: 5 | C7: ET | D7: Get training E&T (Competency matrix) | E7: Thu Duong | F7: 46101 | G7: Done | H7: Book meeting with Duy Pham - Done
B8: 6 | C8: OE | D8: Build Assessment checklist for all Pillar | E8: Duy Pham | F8: 46108 | G8: Done | H8: Done
B9: 7 | C9: OE | D9: Propose Award budget for certificated | E9: Duy Pham | F9: 46108 | G9: Done | H9: Done
B10: 8 | C10: ET | D10: Kick-off E&T to implementation | E10: Thu Duong | F10: 10-04-2026 16-Apr | G10: Done | H10: Thu collect E&T link with HODs-Done
B11: 9 | C11: PM | D11: Review timing of facility in PM Key activities | E11: Anh Truong | F11: 46122 | G11: Done
B12: 10 | C12: FI | D12: FI book monthly meeting to review RCA effectiveness | E12: Vu Tran | F12: 46122 | G12: Done
B13: 11 | C13: Q | D13: Adding measure to tracking NC | E13: Duy Pham | F13: 46108 | G13: Done
B14: 12 | C14: OE | D14: Final the prizes & group to recognition | E14: Duc Mai | F14: 10-04-2026 16-Apr | G14: Done | H14: Total: 86tr/year
B15: 13 | C15: GA | D15: Create new measure & SHO instruction (Video instruction) | E15: Dung Tran | F15: 46129 | G15: Done
B16: 14 | C16: OE | D16: Tìm cách monitor kết quả tại từng khu vực sau khi pass đánh giá | E16: Duy Pham | F16: 46137 | G16: Done
B17: 15 | C17: OE | D17: Nominate project completed in Q1 & evaluation for recognition | E17: Duy Pham | F17: 46122 | G17: Done | H17: Done
B18: 16 | C18: OE | D18: Create reward list for factory & aligned | E18: Duy Pham | F18: 46129 | G18: Done | H18: Book meeting to final
B19: 17 | C19: ET | D19: Finalize CM of Production | E19: Duy Pham | F19: 46122 | G19: Done | H19: Done
B20: 18 | C20: ET | D20: Build Multi-skilled implementation plan | E20: Thu Duong | F20: 46122 | G20: Done | H20: Duy Support - Done
B21: 19 | C21: ET | D21: Finalize E&T key activities with chị Yến | E21: Duy Pham | F21: 10-04-2026 16-Apr | G21: Done | H21: Done
B22: 20 | C22: FI | D22: Sent IPA in Mar (detail % OPL/EPL,...) | E22: Vu Tran | F22: 46128 | G22: Done
B23: 21 | C23: PM | D23: Book monthly meeting to review Work order | E23: Anh Truong | F23: 46128 | G23: Done
B24: 22 | C24: OE | D24: Propose rules for OE meeting attendance | E24: Duy Pham | F24: 46128 | G24: Done | H24: Done
B25: 23 | C25: OE | D25: Discuss to increase nominal speed of FD (740 to 750 kg/hr) | E25: Duc Mai | F25: 46128 | G25: Done | H25: Done - Keep 740 kgs/h
B26: 24 | C26: ET | D26: Collect Multi skill plan & participant of all team | E26: Yen Tran | F26: 07-05-2026 13-May | G26: Done | H26: Pending Eng/PRO | I26: 1
B27: 25 | C27: ET | D27: Collect form (assessment checklist, posttest,…) of multi skill program for all department | E27: Thu Duong | F27: 46157 | G27: Done | H27: Upload lên folder
B28: 26 | C28: GA | D28: Book session gemba WOR of Engineering | E28: Dung Tran | F28: 46150 | G28: Done
B29: 27 | C29: AM | D29: Book re-assessment for FD/FP area | E29: Duy Pham | F29: 46150 | G29: Done | H29: Done
B30: 28 | C30: PM | D30: Final spare part management of FD | E30: Anh Truong | F30: 15-05-2026 31-May 12-Jun | G30: Done | I30: 2
B31: 29 | C31: PM | D31: Review work order in Quarter 1 & April (involve all relevant department) | E31: Anh Truong | F31: 29-04-2026 15-May | G31: Done | H31: Send invitation to all department Share link of WO progress
B32: 30 | C32: PM | D32: Completed PM of facility | E32: Anh Truong | F32: 02-05-2026 15-May | G32: Done | H32: Upload lên DMS
B33: 31 | C33: GA | D33: Book session gemba WOR of QA | E33: Vu Tran | F33: 46150 | G33: Done
B34: 32 | C34: GA | D34: Finetune SHO instruction & apply for team | E34: Duy Pham | F34: 15-05-2026 25-May | G34: Done | H34: Done | I34: 1
B35: 33 | C35: PM | D35: Completed Spare part management for EXT | E35: Anh Truong | F35: 46163 | G35: Done
B36: 34 | C36: FI | D36: Monthly Review RCA Effectiveness in Apr | E36: Vu Tran | F36: 46157 | G36: Done
B37: 35 | C37: Q | D37: Clarify expectation of Q line mapping | E37: Binh Dang | F37: 46157 | G37: Done
B38: 36 | C38: ET | D38: Collect multi skilled achievement in Quarter 2 | E38: Thu Duong | F38: 21-06-2026 10-07 | G38: Done
B39: 37 | C39: Q | D39: Complete Q Line mapping of Micro | E39: Binh Dang | F39: 46173 | G39: Done
B40: 38 | C40: Q | D40: Complete Q Line mapping of FB | E40: Binh Dang | F40: 46173 | G40: Done
...

Sheet 7. KPI Measure
A1: BUSINESS TARGET 2026

Sheet KPI data tracking
A1: BUSINESS TARGET 2026
A2: PIC | B2: Duc Mai | D2: Duy Pham | F2: Vu Tran | H2: Vu Tran | J2: Yen Tran | L2: Hoang Nguyen | N2: Dung Tran | P2: Dung Tran | R2: Hoang Nguyen | T2: Dung Tran | V2: Dung Tran
A3: KPI | B3: CONVERTED VOLUME | D3: RW GENERATION | F3: YIELD OF VG2 | H3: YIELD OF CONILON | J3: TURN-OVER | L3: LTI | N3: MAJOR COMPLAINT | P3: OTHER COMPLAINT | R3: MAJOR FINDING | T3: CERT. RENEWAL | V3: TOTAL NC
A4: Month | B4: Target | C4: Actual | D4: Target | E4: Actual | F4: Target | G4: Actual | H4: Target | I4: Actual | J4: Target | K4: Actual | L4: Target | M4: Actual | N4: Target | O4: Actual | P4: Target | Q4: Actual | R4: Target | S4: Actual | T4: Target | U4: Actual | V4: Target | W4: Actual | X4: Top Defect
A5: Jan | B5: 478987.2 | C5: 487541.56 | D5: 4000 | E5: 1040 | F5: 2.01 | G5: 2.01 | H5: 2 | I5: 2.01 | J5: 0.8 | K5: 0 | L5: 0 | M5: 0 | N5: 0 | O5: 0 | P5: 0.5 | Q5: 0 | R5: 0 | S5: 0 | T5: 1 | U5: 1 | V5: 20000 | W5: 25044 | X5: 1. Micro: 14040 2. Organic: 3978 3. Out sensory: 1038
A6: Feb | B6: 429436.8 | C6: 468406 | D6: 4000 | E6: 380 | F6: 2.01 | G6: 1.99 | H6: 2 | I6: 2.01 | J6: 0.8 | K6: 0 | L6: 0 | M6: 0 | N6: 0 | O6: 0 | P6: 0.5 | Q6: 1 | R6: 0 | S6: 0 | T6: 1 | U6: 1 | V6: 20000 | W6: 10508
A7: Mar | B7: 396403.2 | C7: 426380 | D7: 4000 | E7: 0 | F7: 2.01 | G7: 1.99 | H7: 2 | I7: NA | J7: 0.8 | K7: 0 | L7: 0 | M7: 0 | N7: 0 | O7: 0 | P7: 0.5 | Q7: 1 | R7: 0 | S7: 0 | T7: 1 | U7: 1 | V7: 20000 | W7: 8358
A8: Apr | B8: 462470.4 | C8: 477410 | D8: 4000 | E8: 0 | F8: 2.01 | G8: 2 | H8: 2 | I8: NA | J8: 0.8 | K8: 1 | L8: 0 | M8: 0 | N8: 0 | O8: 0 | P8: 0.5 | Q8: 0 | R8: 0 | S8: 0 | T8: 1 | U8: 1 | V8: 20000 | W8: 7120
A9: May | B9: 478987.2 | C9: 492932 | D9: 4000 | E9: 1420 | F9: 2.01 | G9: 2 | H9: 2 | I9: NA | J9: 0.8 | K9: 0 | L9: 0 | M9: 0 | N9: 0 | O9: 0 | P9: 0.5 | Q9: 0 | R9: 0 | S9: 0 | T9: 1 | U9: 1 | V9: 20000 | W9: 10695
A10: Jun | B10: 462470.4 | C10: 491563 | D10: 4000 | E10: 300 | F10: 2.01 | G10: 1.99 | H10: 2 | I10: NA | J10: 0.8 | K10: 0 | L10: 0 | M10: 0 | N10: 0 | O10: 0 | P10: 0.5 | Q10: 0 | R10: 0 | S10: 0 | T10: 1 | U10: 1 | V10: 20000 | W10: 10652
A11: Jul | B11: 478987.2 | C11: 509266 | D11: 4000 | E11: 350 | F11: 2.01 | G11: 1.99 | H11: 2 | I11: NA | J11: 0.8 | K11: 1 | L11: 0 | M11: 0 | N11: 0 | O11: 0 | P11: 0.5 | Q11: 1 | R11: 0 | S11: 0 | T11: 1 | U11: 1 | V11: 20000 | W11: 2510
A12: Aug | B12: 478987.2 | D12: 4000 | F12: 2.01 | H12: 2 | J12: 0.8 | L12: 0 | N12: 0 | P12: 0.5 | R12: 0 | T12: 1 | V12: 20000
A13: Sep | B13: 462470.4 | D13: 4000 | F13: 2.01 | H13: 2 | J13: 0.8 | L13: 0 | N13: 0 | P13: 0.5 | R13: 0 | T13: 1 | V13: 20000
A14: Oct | B14: 478987.2 | D14: 4000 | F14: 2.01 | H14: 2 | J14: 0.8 | L14: 0 | N14: 0 | P14: 0.5 | R14: 0 | T14: 1 | V14: 20000
A15: Nov | B15: 462470.4 | D15: 4000 | F15: 2.01 | H15: 2 | J15: 0.8 | L15: 0 | N15: 0 | P15: 0.5 | R15: 0 | T15: 1 | V15: 20000
A16: Dec | B16: 478987.2 | D16: 4000 | F16: 2.01 | H16: 2 | J16: 0.8 | L16: 0 | N16: 0 | P16: 0.5 | R16: 0 | T16: 1 | V16: 20000
A17: YTD | B17: =SUM(B5:B16) -> 5549644.8 | C17: =SUM(C5:C16) -> 3353498.6 | D17: =SUM(D5:D16) -> 48000 | E17: =SUM(E5:E16) -> 3490 | F17: =AVERAGE(F5:F16) -> 2.01 | G17: =AVERAGE(G5:G16) -> 1.9957143 | H17: =AVERAGE(H5:H16) -> 2 | I17: =AVERAGE(I5:I16) -> 2.01 | J17: =SUM(J5:J16) -> 9.6 | K17: =SUM(K5:K16) -> 2 | L17: 0 | M17: =SUM(M5:M16) -> 0 | N17: 0 | O17: =SUM(O5:O16) -> 0 | P17: 6 | Q17: =SUM(Q5:Q16) -> 3 | R17: 0 | S17: =SUM(S5:S16) -> 0 | T17: 1 | U17: =AVERAGE(U5:U16) -> 1 | V17: =SUM(V5:V16) -> 240000 | W17: =SUM(W5:W16) -> 74887

Sheet OE meeting rules
A1: OE MEETING RULES | I1: OE Team Fund Tracking
A2: No | B2: VIOLATE | C2: RULE | D2: NOTE | I2: task | J2: date | K2: Contribute | L2: payment
A3: 1 | B3: Tham gia meeting trễ giờ | C3: 20000 | D3: Trễ 1' sau khi start meeting | I3: Budget | J3: 46136 | K3: ='03. Attendance'!$AL$14 -> 7200000 | L3: 0
A4: 2 | B4: Không tham gia meeting | C4: 50000 | D4: Không chấp nhận lí do | I4: Fine paid | J4: 46150 | K4: ='03. Attendance'!$AD$14 -> 340000 | L4: 0
A5: 3 | B5: Trễ action/Milestone | C5: 10000 | D5: 1 lần | I5: Fruit | J5: 46150 | L5: -179000
I6: Fruit | J6: 46164 | L6: -200000
A7: QUỸ OE: 100k/member/tháng . Manager: 200k/tháng | I7: 1st Engagement lunch in Quarter 2 | J7: 46164 | L7: -1683000
A8: 1 | B8: Chuẩn bị trái cây cho meeting | C8: 2 lần/tháng | D8: Thu Duong | I8: Fruit | J8: 46178 | L8: -100000
A9: 2 | B9: OE team engagement | C9: 2 lần/quý | D9: Duy Pham | I9: 2nd Engagement lunch in Quarter 2 | J9: 46192 | L9: -1824000
A10: Tiền phạt sẽ xung công để phục vụ cho team. Thu quỹ bắt đầu từ tháng 4 | I10: 1st Engagement lunch in Quarter 3 | J10: 46237 | L10: -1954000
A12: Thủ Qũy: Thu Duong | I12: Fruit | J12: 46248 | L12: -217154
J14: Total | K14: =SUM(K3:K13) -> 7540000 | L14: =SUM(L3:L13) -> -6157154
K15: Remain | L15: =SUM(K3:L13) -> 1382846

Sheet Engagement plan
A1: 2026-OE TEAM ENGAGEMENT PLAN | F1: 2nd Engagement lunch in Quarter 3 - 11/9
A2: No | B2: Activity | C2: Time | D2: Status | F2: No. | G2: Menu | H2: Prize | I2: Qyt | J2: Total
A3: 1 | B3: 1st Engagement lunch in Quarter 2 | C3: May | D3: Done | F3: 1 | G3: Cơm chiên trùm trứng | H3: 57000 | I3: 2 | J3: =I3*H3 -> 114000
A4: 2 | B4: 2nd Engagement lunch in Quarter 2 | C4: Jun | D4: Done | F4: 2 | G4: Đuôi heo chiên giòn | H4: 127000 | I4: 2 | J4: =I4*H4 -> 254000
A5: 3 | B5: 1st Engagement lunch in Quarter 3 | C5: Jul | D5: Done | F5: 3 | G5: Rau luộc kho quẹt | H5: 67000 | I5: 2 | J5: =I5*H5 -> 134000
A6: 4 | B6: 2nd Engagement lunch in Quarter 3 | C6: Sep | F6: 4 | G6: Cá diêu hồng chiên xù bánh tráng + rau | H6: 197000 | I6: 2 | J6: =I6*H6 -> 394000
A7: 5 | B7: 1st Engagement lunch in Quarter 4 | C7: Oct | F7: 5 | G7: Lẩu thái | H7: 247000 | I7: 2 | J7: =I7*H7 -> 494000
A8: 6 | B8: 2nd Engagement lunch in Quarter 4 | C8: Dec | F8: 6 | G8: Tráng miệng | H8: 30000 | I8: 2 | J8: =I8*H8 -> 60000
F9: 7 | G9: Nước | H9: 15000 | I9: 12 | J9: =I9*H9 -> 180000
J10: =SUM(J3:J9) -> 1630000
